<robot name="iCub">
    <link name="base_link" />
    <joint name="base_fixed_joint" type="fixed">
        <origin xyz="0 0 0" rpy="0 -0 0" />
        <axis xyz="0 0 0" />
        <parent link="base_link" />
        <child link="root_link" />
    </joint>
    <link name="root_link">
      <inertial>
        <origin xyz="0.0248821 0.000103947 -0.0440806" rpy="1.57079632679 0 -1.57079632679"/>
        <mass value="5.09143"/>
        <inertia ixx="0.0139679" ixy="-5.93488e-06" ixz="-1.55458e-05" iyy="0.0202112" iyz="-0.00170968" izz="0.0249124"/>
      </inertial>
      <visual>
        <origin xyz="-0.0364 0 0.032" rpy="1.57079632679 0 -1.57079632679"/>
        <geometry>
          <mesh filename="model://iCubGenova02/meshes/dae/root.dae" scale="0.001 0.001 0.001"/>
        </geometry>
        <material name="green">
          <color rgba="0 1 0 1"/>
        </material>
      </visual>
      <collision>
        <origin xyz="-0.0364 0 0.032" rpy="1.57079632679 0 -1.57079632679"/>
        <geometry>
          <mesh filename="model://iCubGenova02/meshes/dae/root.dae" scale="0.001 0.001 0.001"/>
        </geometry>
      </collision>
    </link>
    <link name="r_hip_1">
        <inertial>
            <mass value="0.754" />
            <origin xyz="0 -0.0782 0" rpy="0 -0 0" />
            <inertia ixx="0" ixy="0" ixz="0" iyy="0" iyz="0" izz="0" />
        </inertial>
        <visual>
            <origin xyz="0 0 0" rpy="-1.3734 -1.5708 -0.380506" />
            <geometry>
                <mesh filename="meshes/visual/icub_r_hip_1.dae" scale="1 1 1" />
            </geometry>
            <material name="material.metal">
                <texture />
                <color rgba="0 0 0 1" />
            </material>
        </visual>
        <collision>
            <origin xyz="0 0 0" rpy="-1.3734 -1.5708 -0.380506" />
            <geometry>
                <mesh filename="meshes/collision/icub_simple_collision_r_hip_1.dae" scale="1 1 1" />
            </geometry>
        </collision>
    </link>
    <joint name="r_hip_pitch" type="revolute">
        <origin xyz="0 0.0681 -0.1199" rpy="-2.77556e-17 1.5708 2.77556e-17" />
        <axis xyz="0 1 6.12323e-17" />
        <parent link="root_link" />
        <child link="r_hip_1" />
        <dynamics damping="1" friction="0" />
        <limit effort="84" velocity="100" lower="-0.767945" upper="2.30383" />
    </joint>
    <link name="r_hip_2">
        <inertial>
            <mass value="0.526" />
            <origin xyz="0 0 0.03045" rpy="0 -0 0" />
            <inertia ixx="-5.42101e-20" ixy="0" ixz="0" iyy="-5.42101e-20" iyz="0" izz="0" />
        </inertial>
        <visual>
            <origin xyz="0 0 0" rpy="0.785327 -1.5708 -0.785327" />
            <geometry>
                <mesh filename="meshes/visual/icub_r_hip_2.dae" scale="1 1 1" />
            </geometry>
            <material name="material.metal">
                <texture />
                <color rgba="0 0 0 1" />
            </material>
        </visual>
        <collision>
            <origin xyz="0 0 0" rpy="0.785327 -1.5708 -0.785327" />
            <geometry>
                <mesh filename="meshes/collision/icub_simple_collision_r_hip_2.dae" scale="1 1 1" />
            </geometry>
        </collision>
    </link>
    <joint name="r_hip_roll" type="revolute">
        <origin xyz="0 0 0" rpy="2.77556e-17 1.5708 -2.77556e-17" />
        <axis xyz="-1 0 6.12323e-17" />
        <parent link="r_hip_1" />
        <child link="r_hip_2" />
        <dynamics damping="1" friction="0" />
        <limit effort="84" velocity="100" lower="-2.07694" upper="0.296706" />
    </joint>
    <link name="r_hip_3">
        <inertial>
            <mass value="0" />
            <origin xyz="0 0 0" rpy="0 -0 0" />
            <inertia ixx="0" ixy="0" ixz="0" iyy="0" iyz="0" izz="0" />
        </inertial>
    </link>
    <joint name="r_leg_ft_sensor" type="fixed">
        <origin xyz="0 0 0.0665" rpy="0 -0 0" />
        <axis xyz="0 0 0" />
        <parent link="r_hip_2" />
        <child link="r_hip_3" />
    </joint>
    <link name="r_upper_leg">
        <inertial>
            <mass value="2.175" />
            <origin xyz="0.00144 -0.15943 0.00039" rpy="0 -0 0" />
            <inertia ixx="0" ixy="0" ixz="0" iyy="4.07592e-18" iyz="-2.71051e-20" izz="0" />
        </inertial>
        <visual>
            <origin xyz="0 0 0" rpy="-1.57072 -1.5708 3.14152" />
            <geometry>
                <mesh filename="meshes/visual/icub_r_thigh.dae" scale="1 1 1" />
            </geometry>
            <material name="material.metal">
                <texture />
                <color rgba="0 0 0 1" />
            </material>
        </visual>
        <collision>
            <origin xyz="0 0 0" rpy="-1.57072 -1.5708 3.14152" />
            <geometry>
                <mesh filename="meshes/collision/icub_simple_collision_r_thigh.dae" scale="1 1 1" />
            </geometry>
        </collision>
    </link>
    <joint name="r_hip_yaw" type="revolute">
        <origin xyz="0 0 -0.0665" rpy="-1.5708 -6.16298e-33 6.12323e-17" />
        <axis xyz="0 -1 6.12323e-17" />
        <parent link="r_hip_3" />
        <child link="r_upper_leg" />
        <dynamics damping="1" friction="0" />
        <limit effort="40" velocity="100" lower="-1.37881" upper="1.37881" />
    </joint>
    <link name="r_lower_leg">
        <inertial>
            <mass value="1.264" />
            <origin xyz="-0.1071 0.00182 -0.00211" rpy="0 -0 0" />
            <inertia ixx="-6.2511e-19" ixy="5.42101e-20" ixz="-5.42101e-20" iyy="-1.73472e-18" iyz="8.47033e-22" izz="-1.73472e-18" />
        </inertial>
        <visual>
            <origin xyz="5.55112e-17 2.28232e-12 -8.32667e-17" rpy="3.14159 -1.14424e-17 1.5708" />
            <geometry>
                <mesh filename="meshes/visual/icub_r_shank.dae" scale="1 1 1" />
            </geometry>
            <material name="material.metal">
                <texture />
                <color rgba="0 0 0 1" />
            </material>
        </visual>
        <collision>
            <origin xyz="5.55112e-17 2.28232e-12 -8.32667e-17" rpy="3.14159 -1.14424e-17 1.5708" />
            <geometry>
                <mesh filename="meshes/collision/icub_simple_collision_r_shank.dae" scale="1 1 1" />
            </geometry>
        </collision>
    </link>
    <joint name="r_knee" type="revolute">
        <origin xyz="0 -0.2236 1.36916e-17" rpy="3.14159 -1.2326e-32 1.5708" />
        <axis xyz="0 1.22465e-16 -1" />
        <parent link="r_upper_leg" />
        <child link="r_lower_leg" />
        <dynamics damping="1" friction="0" />
        <limit effort="30" velocity="100" lower="-2.18166" upper="0.401426" />
    </joint>
    <link name="r_ankle_1">
        <inertial>
            <mass value="0.746" />
            <origin xyz="-0.0054 0.00163 -0.0172" rpy="0 -0 0" />
            <inertia ixx="2.71051e-20" ixy="-1.69407e-21" ixz="1.35525e-20" iyy="5.42101e-20" iyz="3.38813e-21" izz="1.35525e-20" />
        </inertial>
        <visual>
            <origin xyz="1.11022e-16 -1.08717e-12 -4.45647e-12" rpy="-1.5708 -1.53106e-11 5.10376e-12" />
            <geometry>
                <mesh filename="meshes/visual/icub_r_ankle_1.dae" scale="1 1 1" />
            </geometry>
            <material name="material.metal">
                <texture />
                <color rgba="0 0 0 1" />
            </material>
        </visual>
        <collision>
            <origin xyz="1.11022e-16 -1.08717e-12 -4.45647e-12" rpy="-1.5708 -1.53106e-11 5.10376e-12" />
            <geometry>
                <mesh filename="meshes/collision/icub_simple_collision_r_ankle_1.dae" scale="1 1 1" />
            </geometry>
        </collision>
    </link>
    <joint name="r_ankle_pitch" type="revolute">
        <origin xyz="-0.213 0 0" rpy="1.5708 -0 0" />
        <axis xyz="0 1 6.12323e-17" />
        <parent link="r_lower_leg" />
        <child link="r_ankle_1" />
        <dynamics damping="1" friction="0" />
        <limit effort="24" velocity="100" lower="-0.733038" upper="0.366519" />
    </joint>
    <link name="r_ankle_2">
        <inertial>
            <mass value="0.2675" />
            <origin xyz="0.008 0 0.0553" rpy="0 -0 0" />
            <inertia ixx="0" ixy="0" ixz="1.35525e-20" iyy="0" iyz="0" izz="0" />
        </inertial>
    </link>
    <joint name="r_ankle_roll" type="revolute">
        <origin xyz="0 0 0" rpy="0.504019 1.5708 -2.63757" />
        <axis xyz="-1 1.22465e-16 0" />
        <parent link="r_ankle_1" />
        <child link="r_ankle_2" />
        <dynamics damping="1" friction="0" />
        <limit effort="11" velocity="100" lower="-0.418879" upper="0.418879" />
    </joint>
    <link name="r_foot">
        <inertial>
            <mass value="0.5935" />
            <origin xyz="0.016069 0.000613931 -0.0467154" rpy="0 -0 0" />
            <inertia ixx="0.00285653" ixy="8.74769e-06" ixz="0.000625247" iyy="0.004116" iyz="1.03358e-05" izz="0.00180731" />
        </inertial>
        <visual>
            <origin xyz="-0.008 1.08717e-12 -0.0553" rpy="0.321762 1.5708 -2.81983" />
            <geometry>
                <mesh filename="meshes/visual/icub_r_foot.dae" scale="1 1 1" />
            </geometry>
            <material name="material.metal">
                <texture />
                <color rgba="0 0 0 1" />
            </material>
        </visual>
        <collision>
            <origin xyz="-0.008 1.08717e-12 -0.0553" rpy="0.321762 1.5708 -2.81983" />
            <geometry>
                <mesh filename="meshes/collision/icub_simple_collision_r_foot.dae" scale="1 1 1" />
            </geometry>
        </collision>
    </link>
    <joint name="r_foot_ft_sensor" type="fixed">
        <origin xyz="0.008 0 0.0553" rpy="0 -0 0" />
        <axis xyz="0 0 0" />
        <parent link="r_ankle_2" />
        <child link="r_foot" />
    </joint>
    <link name="r_sole">
        <inertial>
            <mass value="0" />
            <origin xyz="0 0 0" rpy="0 -0 0" />
            <inertia ixx="0" ixy="0" ixz="0" iyy="0" iyz="0" izz="0" />
        </inertial>
    </link>
    <joint name="r_sole_fixed_joint" type="fixed">
        <origin xyz="-0.0263 -1.38778e-17 -0.0143" rpy="3.14159 -0 0" />
        <axis xyz="0 0 0" />
        <parent link="r_foot" />
        <child link="r_sole" />
    </joint>
    <link name="l_hip_1">
        <inertial>
            <mass value="0.754" />
            <origin xyz="0 -0.0782 0" rpy="0 -0 0" />
            <inertia ixx="0.000471076" ixy="2.059e-06" ixz="1.451e-06" iyy="0.000346478" iyz="1.545e-06" izz="0.000510315" />
        </inertial>
        <visual>
            <origin xyz="0 0 0" rpy="2.35619 1.5708 0.785398" />
            <geometry>
                <mesh filename="meshes/visual/icub_l_hip_1.dae" scale="1 1 1" />
            </geometry>
            <material name="material.metal">
                <texture />
                <color rgba="0 0 0 1" />
            </material>
        </visual>
        <collision>
            <origin xyz="0 0 0" rpy="2.35619 1.5708 0.785398" />
            <geometry>
                <mesh filename="meshes/collision/icub_simple_collision_l_hip_1.dae" scale="1 1 1" />
            </geometry>
        </collision>
    </link>
    <joint name="l_hip_pitch" type="revolute">
        <origin xyz="0 -0.0681 -0.1199" rpy="-3.14159 1.5708 -2.77556e-17" />
        <axis xyz="0 -1 6.12323e-17" />
        <parent link="root_link" />
        <child link="l_hip_1" />
        <dynamics damping="1" friction="0" />
        <limit effort="84" velocity="100" lower="-0.767945" upper="2.30383" />
    </joint>
    <link name="l_hip_2">
        <inertial>
            <mass value="0.526" />
            <origin xyz="0 0 0.03045" rpy="0 -0 0" />
            <inertia ixx="0.000561583" ixy="-7.4e-08" ixz="1.0835e-05" iyy="0.000738049" iyz="-6.2e-08" izz="0.000294119" />
        </inertial>
        <visual>
            <origin xyz="0 0 0" rpy="-2.35623 -1.5708 -0.785361" />
            <geometry>
                <mesh filename="meshes/visual/icub_l_hip_2.dae" scale="1 1 1" />
            </geometry>
            <material name="material.metal">
                <texture />
                <color rgba="0 0 0 1" />
            </material>
        </visual>
        <collision>
            <origin xyz="0 0 0" rpy="-2.35623 -1.5708 -0.785361" />
            <geometry>
                <mesh filename="meshes/collision/icub_simple_collision_l_hip_2.dae" scale="1 1 1" />
            </geometry>
        </collision>
    </link>
    <joint name="l_hip_roll" type="revolute">
        <origin xyz="0 0 0" rpy="3.14159 -1.5708 -2.77556e-17" />
        <axis xyz="1 0 -6.12323e-17" />
        <parent link="l_hip_1" />
        <child link="l_hip_2" />
        <dynamics damping="1" friction="0" />
        <limit effort="84" velocity="100" lower="-2.07694" upper="0.296706" />
    </joint>
    <link name="l_hip_3">
        <inertial>
            <mass value="0" />
            <origin xyz="0 0 0" rpy="0 -0 0" />
            <inertia ixx="0" ixy="0" ixz="0" iyy="0" iyz="0" izz="0" />
        </inertial>
    </link>
    <joint name="l_leg_ft_sensor" type="fixed">
        <origin xyz="0 0 0.0665" rpy="0 -0 0" />
        <axis xyz="0 0 0" />
        <parent link="l_hip_2" />
        <child link="l_hip_3" />
    </joint>
    <link name="l_upper_leg">
        <inertial>
            <mass value="2.175" />
            <origin xyz="0.00144 -0.15943 -0.00039" rpy="0 -0 0" />
            <inertia ixx="0.00759107" ixy="-6.726e-05" ixz="2.267e-06" iyy="0.00142302" iyz="3.63726e-05" izz="0.00755385" />
        </inertial>
        <visual>
            <origin xyz="0 0 0" rpy="0.463626 1.5708 2.03443" />
            <geometry>
                <mesh filename="meshes/visual/icub_l_thigh.dae" scale="1 1 1" />
            </geometry>
            <material name="material.metal">
                <texture />
                <color rgba="0 0 0 1" />
            </material>
        </visual>
        <collision>
            <origin xyz="0 0 0" rpy="0.463626 1.5708 2.03443" />
            <geometry>
                <mesh filename="meshes/collision/icub_simple_collision_l_thigh.dae" scale="1 1 1" />
            </geometry>
        </collision>
    </link>
    <joint name="l_hip_yaw" type="revolute">
        <origin xyz="0 0 -0.0665" rpy="-1.5708 -6.16298e-33 -6.12323e-17" />
        <axis xyz="0 1 6.12323e-17" />
        <parent link="l_hip_3" />
        <child link="l_upper_leg" />
        <dynamics damping="1" friction="0" />
        <limit effort="40" velocity="100" lower="-1.37881" upper="1.37881" />
    </joint>
    <link name="l_lower_leg">
        <inertial>
            <mass value="1.264" />
            <origin xyz="-0.1071 0.00182 0.00211" rpy="0 -0 0" />
            <inertia ixx="0.00099895" ixy="-0.000185699" ixz="-6.3147e-05" iyy="0.00445054" iyz="7.86e-07" izz="0.00420766" />
        </inertial>
        <visual>
            <origin xyz="5.55112e-17 2.28232e-12 2.2823e-12" rpy="-3.14159 -2.33487e-16 1.5708" />
            <geometry>
                <mesh filename="meshes/visual/icub_l_shank.dae" scale="1 1 1" />
            </geometry>
            <material name="material.metal">
                <texture />
                <color rgba="0 0 0 1" />
            </material>
        </visual>
        <collision>
            <origin xyz="5.55112e-17 2.28232e-12 2.2823e-12" rpy="-3.14159 -2.33487e-16 1.5708" />
            <geometry>
                <mesh filename="meshes/collision/icub_simple_collision_l_shank.dae" scale="1 1 1" />
            </geometry>
        </collision>
    </link>
    <joint name="l_knee" type="revolute">
        <origin xyz="0 -0.2236 -1.36916e-17" rpy="3.14159 -1.2326e-32 1.5708" />
        <axis xyz="0 1.22465e-16 -1" />
        <parent link="l_upper_leg" />
        <child link="l_lower_leg" />
        <dynamics damping="1" friction="0" />
        <limit effort="30" velocity="100" lower="-2.18166" upper="0.401426" />
    </joint>
    <link name="l_ankle_1">
        <inertial>
            <mass value="0.746" />
            <origin xyz="-0.0054 0.00163 0.0172" rpy="0 -0 0" />
            <inertia ixx="0.00063323" ixy="-7.081e-06" ixz="4.1421e-05" iyy="0.00068776" iyz="2.0817e-05" izz="0.000313897" />
        </inertial>
        <visual>
            <origin xyz="1.11022e-16 -5.54343e-12 4.45647e-12" rpy="1.5708 1.53106e-11 1.53105e-11" />
            <geometry>
                <mesh filename="meshes/visual/icub_l_ankle_1.dae" scale="1 1 1" />
            </geometry>
            <material name="material.metal">
                <texture />
                <color rgba="0 0 0 1" />
            </material>
        </visual>
        <collision>
            <origin xyz="1.11022e-16 -5.54343e-12 4.45647e-12" rpy="1.5708 1.53106e-11 1.53105e-11" />
            <geometry>
                <mesh filename="meshes/collision/icub_simple_collision_l_ankle_1.dae" scale="1 1 1" />
            </geometry>
        </collision>
    </link>
    <joint name="l_ankle_pitch" type="revolute">
        <origin xyz="-0.213 0 0" rpy="-1.5708 0 0" />
        <axis xyz="0 -1 6.12323e-17" />
        <parent link="l_lower_leg" />
        <child link="l_ankle_1" />
        <dynamics damping="1" friction="0" />
        <limit effort="24" velocity="100" lower="-0.733038" upper="0.366519" />
    </joint>
    <link name="l_ankle_2">
        <inertial>
            <mass value="0.2675" />
            <origin xyz="0.008 0 0.0553" rpy="0 -0 0" />
            <inertia ixx="0" ixy="0" ixz="1.35525e-20" iyy="0" iyz="0" izz="0" />
        </inertial>
    </link>
    <joint name="l_ankle_roll" type="revolute">
        <origin xyz="0 0 0" rpy="0 -1.5708 0" />
        <axis xyz="1 0 0" />
        <parent link="l_ankle_1" />
        <child link="l_ankle_2" />
        <dynamics damping="1" friction="0" />
        <limit effort="11" velocity="100" lower="-0.418879" upper="0.418879" />
    </joint>
    <link name="l_foot">
        <inertial>
            <mass value="0.5935" />
            <origin xyz="0.016069 -0.000613931 -0.0467154" rpy="0 -0 0" />
            <inertia ixx="0.00285654" ixy="-8.74769e-06" ixz="0.000625247" iyy="0.004116" iyz="-1.03356e-05" izz="0.00180731" />
        </inertial>
        <visual>
            <origin xyz="-0.008 -5.54343e-12 -0.0553" rpy="2.35619 1.5708 2.35619" />
            <geometry>
                <mesh filename="meshes/visual/icub_l_foot.dae" scale="1 1 1" />
            </geometry>
            <material name="material.metal">
                <texture />
                <color rgba="0 0 0 1" />
            </material>
        </visual>
        <collision>
            <origin xyz="-0.008 -5.54343e-12 -0.0553" rpy="2.35619 1.5708 2.35619" />
            <geometry>
                <mesh filename="meshes/collision/icub_simple_collision_l_foot.dae" scale="1 1 1" />
            </geometry>
        </collision>
    </link>
    <joint name="l_foot_ft_sensor" type="fixed">
        <origin xyz="0.008 0 0.0553" rpy="0 -0 0" />
        <axis xyz="0 0 0" />
        <parent link="l_ankle_2" />
        <child link="l_foot" />
    </joint>
    <link name="l_sole">
        <inertial>
            <mass value="0" />
            <origin xyz="0 0 0" rpy="0 -0 0" />
            <inertia ixx="0" ixy="0" ixz="0" iyy="0" iyz="0" izz="0" />
        </inertial>
    </link>
    <joint name="l_sole_fixed_joint" type="fixed">
        <origin xyz="-0.0263 -5.66898e-35 -0.0143" rpy="3.14159 -0 0" />
        <axis xyz="0 0 0" />
        <parent link="l_foot" />
        <child link="l_sole" />
    </joint>
    <link name="torso_1">
      <inertial>
        <origin xyz="0.0270921359 0.02914798 -0.0004398" rpy="0 0 0"/>
        <mass value="0.67144"/>
        <inertia ixx="0.00040911" ixy="-1.04522e-06" ixz="-1.02516e-06" iyy="0.000384141" iyz="6.50708e-06" izz="0.000299445"/>
      </inertial>
      <visual>
        <origin xyz="0.0270462998093 0.032 0.0364" rpy="0 0 0"/>
        <geometry>
          <mesh filename="model://iCubGenova02/meshes/dae/torso_1.dae" scale="0.001 0.001 0.001"/>
        </geometry>
        <material name="pink"/>
      </visual>
      <collision>
        <origin xyz="0.0270462998093 0.032 0.0364" rpy="0 0 0"/>
        <geometry>
          <mesh filename="model://iCubGenova02/meshes/dae/torso_1.dae" scale="0.001 0.001 0.001"/>
        </geometry>
      </collision>
    </link>
    <joint name="torso_pitch" type="revolute">
      <origin xyz="0 0.0270463 0" rpy="1.57079632679 0 -1.57079632679"/>
      <axis xyz="1.0 0.0 0.0"/>
      <parent link="root_link"/>
      <child link="torso_1"/>
      <limit effort="50000" lower="-0.349065850399" upper="1.2217304764" velocity="50000"/>
      <dynamics damping="0.06"/>
    </joint>
    <link name="torso_2">
      <inertial>
        <origin xyz="-0.000112850809265 0.036182 0.0576606" rpy="0 0 0"/>
        <mass value="0.428161"/>
        <inertia ixx="0.000833014" ixy="2.2275e-08" ixz="8.1931e-08" iyy="0.000440576" iyz="-6.00823e-07" izz="0.000605488"/>
      </inertial>
      <visual>
        <origin xyz="0 0.1433 0.0389982" rpy="0 0 0"/>
        <geometry>
          <mesh filename="model://iCubGenova02/meshes/dae/torso_2.dae" scale="0.001 0.001 0.001"/>
        </geometry>
        <material name="cyan"/>
      </visual>
      <collision>
        <origin xyz="0 0.1433 0.0389982" rpy="0 0 0"/>
        <geometry>
          <mesh filename="model://iCubGenova02/meshes/dae/torso_2.dae" scale="0.001 0.001 0.001"/>
        </geometry>
      </collision>
    </link>
    <joint name="torso_roll" type="revolute">
      <origin xyz="0.0270462998093 0.032 -0.0576906" rpy="0 0 0"/>
      <axis xyz="0.0 0.0 -1.0"/>
      <parent link="torso_1"/>
      <child link="torso_2"/>
      <limit effort="50000" lower="-0.523598775598" upper="0.523598775598" velocity="50000"/>
      <dynamics damping="0.06"/>
    </joint>
    <link name="chest">
      <inertial>
        <origin xyz="0.000188619190735 0.023091 -0.013238" rpy="0 0 0"/>
        <mass value="5.638"/>
        <inertia ixx="0.0430324878618" ixy="2.91075388804e-05" ixz="0.000181985229949" iyy="0.0440835725548" iyz="-0.000429106409108" izz="0.0260563249911"/>
      </inertial>
      <visual>
        <origin xyz="0 0.0928 -0.0241889" rpy="0 0 0"/>
        <geometry>
          <mesh filename="model://iCubGenova02/meshes/dae/bb_chest.dae" scale="0.001 0.001 0.001"/>
        </geometry>
        <material name="green"/>
      </visual>
      <collision>
        <origin xyz="0 0.0928 -0.0241889" rpy="0 0 0"/>
        <geometry>
          <mesh filename="model://iCubGenova02/meshes/dae/bb_chest.dae" scale="0.001 0.001 0.001"/>
        </geometry>
      </collision>
    </link>
    <joint name="torso_yaw" type="revolute">
      <origin xyz="0 0.05 0.0631871" rpy="0 0 0"/>
      <axis xyz="0.0 -1.0 0.0"/>
      <parent link="torso_2"/>
      <child link="chest"/>
      <limit effort="50000" lower="-0.872664625997" upper="0.872664625997" velocity="50000"/>
      <dynamics damping="0.06"/>
    </joint>
    <link name="r_shoulder_1">
      <inertial>
        <origin xyz="-0.0122656514133 3.2e-05 -0.00321072950703" rpy="0 0 0"/>
        <mass value="0.114862"/>
        <inertia ixx="2.24541e-05" ixy="-1.65173e-08" ixz="-3.55626e-06" iyy="2.29582e-05" iyz="-6.13337e-08" izz="1.00116e-05"/>
      </inertial>
      <visual>
        <origin xyz="0.0990078953076 0 -0.0265293007173" rpy="0 0 0"/>
        <geometry>
          <mesh filename="model://iCubGenova02/meshes/dae/r_shoulder_1.dae" scale="0.001 0.001 0.001"/>
        </geometry>
        <material name="white"/>
      </visual>
      <collision>
        <origin xyz="0.0990078953076 0 -0.0265293007173" rpy="0 0 0"/>
        <geometry>
          <mesh filename="model://iCubGenova02/meshes/dae/r_shoulder_1.dae" scale="0.001 0.001 0.001"/>
        </geometry>
      </collision>
    </link>
    <joint name="r_shoulder_pitch" type="revolute">
      <origin xyz="-0.120015999809 0.0928 0.0079694" rpy="0 -0.523598883792 3.14159265359"/>
      <axis xyz="-0.965925926173 0.0 0.258819275525"/>
      <parent link="chest"/>
      <child link="r_shoulder_1"/>
      <limit effort="50000" lower="-1.66678943565" upper="0.174532925199" velocity="50000"/>
      <dynamics damping="0.06"/>
    </joint>
    <link name="r_shoulder_2">
      <inertial>
        <origin xyz="-0.0214141959438 0.000271699390655 -0.0194403277547" rpy="0 0 0"/>
        <mass value="0.238162"/>
        <inertia ixx="0.000158626" ixy="-1.12091e-07" ixz="1.02574e-05" iyy="0.000206526" iyz="1.19785e-06" izz="0.000104956"/>
      </inertial>
      <visual>
        <origin xyz="0.106587808568 2.31914715418e-07 -0.0407392121175" rpy="0 0 0"/>
        <geometry>
          <mesh filename="model://iCubGenova02/meshes/dae/r_shoulder_2.dae" scale="0.001 0.001 0.001"/>
        </geometry>
        <material name="dblue"/>
      </visual>
      <collision>
        <origin xyz="0.106587808568 2.31914715418e-07 -0.0407392121175" rpy="0 0 0"/>
        <geometry>
          <mesh filename="model://iCubGenova02/meshes/dae/r_shoulder_2.dae" scale="0.001 0.001 0.001"/>
        </geometry>
      </collision>
    </link>
    <joint name="r_shoulder_roll" type="revolute">
      <origin xyz="-0.00758046573227 0 0.0142102463639" rpy="-0.270597611583 -0.252680154648 -1.50155680035"/>
      <axis xyz="-0.258819 -2.77555756156e-17 -0.965926"/>
      <parent link="r_shoulder_1"/>
      <child link="r_shoulder_2"/>
      <limit effort="50000" lower="0.0" upper="2.80648943721" velocity="50000"/>
      <dynamics damping="0.06"/>
    </joint>
    <link name="r_shoulder_3">
      <inertial>
        <origin xyz="-0.0267620766871 -6.99999999998e-06 0.0146999207713" rpy="0 0 0"/>
        <mass value="0.35913"/>
        <inertia ixx="0.000142333" ixy="3.60361e-07" ixz="4.94445e-05" iyy="0.000197746" iyz="2.65919e-07" izz="0.000151821"/>
      </inertial>
      <visual>
        <origin xyz="0.131933879164 0 -0.0353515667647" rpy="0 0 0"/>
        <geometry>
          <mesh filename="model://iCubGenova02/meshes/dae/r_shoulder_3.dae" scale="0.001 0.001 0.001"/>
        </geometry>
        <material name="dgreen"/>
      </visual>
      <collision>
        <origin xyz="0.131933879164 0 -0.0353515667647" rpy="0 0 0"/>
        <geometry>
          <mesh filename="model://iCubGenova02/meshes/dae/r_shoulder_3.dae" scale="0.001 0.001 0.001"/>
        </geometry>
      </collision>
    </link>
    <joint name="r_shoulder_yaw" type="revolute">
      <origin xyz="-0.0253460713232 2.32750427306e-07 -0.00538764806457" rpy="-0.252689546175 0.0085186183214 0.067039889142"/>
      <axis xyz="0.965925843882 -2.22044604925e-16 -0.258818979447"/>
      <parent link="r_shoulder_2"/>
      <child link="r_shoulder_3"/>
      <limit effort="50000" lower="-0.645771823238" upper="1.3962634016" velocity="50000"/>
      <dynamics damping="0.06"/>
    </joint>
    <link name="r_upper_arm">
      <inertial>
        <origin xyz="-0.006087 0.000126 0.0293121" rpy="0 1.30899700697 0"/>
        <mass value="0.745104"/>
        <inertia ixx="0.000509527" ixy="1.19292e-06" ixz="-1.17426e-05" iyy="0.000668487" iyz="1.13363e-06" izz="0.000599254"/>
      </inertial>
      <visual>
        <origin xyz="-0.015 0 -0.1933" rpy="0 1.30899700697 0"/>
        <geometry>
          <mesh filename="model://iCubGenova02/meshes/dae/r_upper_arm.dae" scale="0.001 0.001 0.001"/>
        </geometry>
        <material name="gray"/>
      </visual>
      <collision>
        <origin xyz="-0.015 0 -0.1933" rpy="0 1.30899700697 0"/>
        <geometry>
          <mesh filename="model://iCubGenova02/meshes/dae/r_upper_arm.dae" scale="0.001 0.001 0.001"/>
        </geometry>
      </collision>
    </link>
    <joint name="r_arm_ft_sensor" type="fixed">
      <origin xyz="-0.0508973017665 0 0.0291670296206" rpy="0 -1.30899700697 0"/>
      <parent link="r_shoulder_3"/>
      <child link="r_upper_arm"/>
      <dynamics damping="0.1"/>
    </joint>
    <link name="r_elbow_1">
      <inertial>
        <origin xyz="-0.0905004201954 0.0184199 0.00918520448611" rpy="0 0 0"/>
        <mass value="1.17637"/>
        <inertia ixx="0.00107282" ixy="-0.000311989" ixz="0.00155336" iyy="0.00689615" iyz="0.000137135" izz="0.00629364"/>
      </inertial>
      <visual>
        <origin xyz="0.259390463317 0.0224999 -0.0850325886962" rpy="0 0 0"/>
        <geometry>
          <mesh filename="model://iCubGenova02/meshes/dae/r_elbow_1.dae" scale="0.001 0.001 0.001"/>
        </geometry>
        <material name="green"/>
      </visual>
      <collision>
        <origin xyz="0.259390463317 0.0224999 -0.0850325886962" rpy="0 0 0"/>
        <geometry>
          <mesh filename="model://iCubGenova02/meshes/dae/r_elbow_1.dae" scale="0.001 0.001 0.001"/>
        </geometry>
      </collision>
    </link>
    <joint name="r_elbow" type="revolute">
      <origin xyz="0 -0.0224999 0.07926" rpy="0 1.30899700697 0"/>
      <axis xyz="2.22044604925e-16 1.0 0.0"/>
      <parent link="r_upper_arm"/>
      <child link="r_elbow_1"/>
      <limit effort="50000" lower="0.261799387799" upper="1.85004900711" velocity="50000"/>
      <dynamics damping="0.06"/>
    </joint>
    <link name="r_forearm">
	    <inertial>
	      <origin xyz="-0.0394796112004 -0.000547 0.00506733794403" rpy="0 0 0"/>
	      <mass value="0.63385"/>
	      <inertia ixx="0.000369432" ixy="-3.85808e-06" ixz="0.000105279" iyy="0.000672046" iyz="5.3443e-06" izz="0.000552077"/>
	    </inertial>
	    <visual>
	      <origin xyz="0.297852893219 0 -0.0798094205022" rpy="0 0 0"/>
	      <geometry>
	        <mesh filename="model://iCubGenova02/meshes/dae/sim_sea_2-5_r_forearm_prt.dae" scale="0.001 0.001 0.001"/>
	      </geometry>
	      <material name="dgreen"/>
	    </visual>
	    <collision>
	      <origin xyz="0.297852893219 0 -0.0798094205022" rpy="0 0 0"/>
	      <geometry>
	        <mesh filename="model://iCubGenova02/meshes/dae/sim_sea_2-5_r_forearm_prt.dae" scale="0.001 0.001 0.001"/>
	      </geometry>
	    </collision>
	</link>
  <joint name="r_wrist_prosup" type="revolute">
    <origin xyz="-0.0384624299027 0.0224999 -0.00522316819403" rpy="0 0 0"/>
    <axis xyz="-0.965925843882 2.22044604925e-16 0.258818979447"/>
    <parent link="r_elbow_1"/>
    <child link="r_forearm"/>
    <limit effort="50000" lower="-1.0471975512" upper="1.0471975512" velocity="50000"/>
    <dynamics damping="0.06"/>
  </joint>
    <link name="l_shoulder_1">
      <inertial>
        <origin xyz="-0.008985 -3.3e-05 -0.0088999" rpy="0 0 0"/>
        <mass value="0.114882"/>
        <inertia ixx="2.24676e-05" ixy="-1.77064e-08" ixz="3.55951e-06" iyy="2.29712e-05" iyz="6.57597e-08" izz="1.00139e-05"/>
      </inertial>
      <visual>
        <origin xyz="-0.120257482 0 -0.032223" rpy="0 0 0"/>
        <geometry>
          <mesh filename="model://iCubGenova02/meshes/dae/l_shoulder_1.dae" scale="0.001 0.001 0.001"/>
        </geometry>
        <material name="black"/>
      </visual>
      <collision>
        <origin xyz="-0.120257482 0 -0.032223" rpy="0 0 0"/>
        <geometry>
          <mesh filename="model://iCubGenova02/meshes/dae/l_shoulder_1.dae" scale="0.001 0.001 0.001"/>
        </geometry>
      </collision>
    </link>
    <joint name="l_shoulder_pitch" type="revolute">
      <origin xyz="0.120016000191 0.0928 0.0079694" rpy="0 0 0"/>
      <axis xyz="0.965926 0.0 0.258819"/>
      <parent link="chest"/>
      <child link="l_shoulder_1"/>
      <limit effort="50000" lower="-1.66678943565" upper="0.174532925199" velocity="50000"/>
      <dynamics damping="0.06"/>
    </joint>
    <link name="l_shoulder_2">
      <inertial>
        <origin xyz="0.0214745701273 0.000268983781583 -0.0194106428522" rpy="0 0 0"/>
        <mass value="0.239074"/>
        <inertia ixx="0.000159206" ixy="1.51033e-07" ixz="-1.04783e-05" iyy="0.000207209" iyz="1.20634e-06" izz="0.000105106"/>
      </inertial>
      <visual>
        <origin xyz="-0.106586716581 1.3668283029e-07 -0.0407432874697" rpy="0 0 0"/>
        <geometry>
          <mesh filename="model://iCubGenova02/meshes/dae/l_shoulder_2.dae" scale="0.001 0.001 0.001"/>
        </geometry>
        <material name="red"/>
      </visual>
      <collision>
        <origin xyz="-0.106586716581 1.3668283029e-07 -0.0407432874697" rpy="0 0 0"/>
        <geometry>
          <mesh filename="model://iCubGenova02/meshes/dae/l_shoulder_2.dae" scale="0.001 0.001 0.001"/>
        </geometry>
      </collision>
    </link>
    <joint name="l_shoulder_roll" type="revolute">
      <origin xyz="-0.013671 0 0.0085203" rpy="0.270597317916 0.252680177542 -1.50155688559"/>
      <axis xyz="-0.258819 2.77555756156e-17 0.965926"/>
      <parent link="l_shoulder_1"/>
      <child link="l_shoulder_2"/>
      <limit effort="50000" lower="0.0" upper="2.80648943721" velocity="50000"/>
      <dynamics damping="0.06"/>
    </joint>
    <link name="l_shoulder_3">
      <inertial>
        <origin xyz="0.026798412222 -1.6e-05 0.0146956806177" rpy="0 0 0"/>
        <mass value="0.35913"/>
        <inertia ixx="0.00014245" ixy="-2.22441e-07" ixz="-4.95846e-05" iyy="0.000197807" iyz="1.07538e-07" izz="0.000151706"/>
      </inertial>
      <visual>
        <origin xyz="-0.131901037685 0 -0.0353427669194" rpy="0 0 0"/>
        <geometry>
          <mesh filename="model://iCubGenova02/meshes/dae/l_shoulder_3.dae" scale="0.001 0.001 0.001"/>
        </geometry>
        <material name="blue"/>
      </visual>
      <collision>
        <origin xyz="-0.131901037685 0 -0.0353427669194" rpy="0 0 0"/>
        <geometry>
          <mesh filename="model://iCubGenova02/meshes/dae/l_shoulder_3.dae" scale="0.001 0.001 0.001"/>
        </geometry>
      </collision>
    </link>
    <joint name="l_shoulder_yaw" type="revolute">
      <origin xyz="0.0253143218312 1.37518334151e-07 -0.00540052326137" rpy="-0.252689546175 -0.0085186183214 -0.067039889142"/>
      <axis xyz="0.965925843882 2.22044604925e-16 0.258818979447"/>
      <parent link="l_shoulder_2"/>
      <child link="l_shoulder_3"/>
      <limit effort="50000" lower="-0.645771823238" upper="1.3962634016" velocity="50000"/>
      <dynamics damping="0.06"/>
    </joint>
    <link name="l_upper_arm">
      <inertial>
        <origin xyz="-0.006121 -0.000189 0.0293684" rpy="0 -1.30899700697 -3.14159265359"/>
        <mass value="0.746799"/>
        <inertia ixx="0.000509731" ixy="-6.90767e-07" ixz="1.20048e-05" iyy="0.00067086" iyz="3.11833e-06" izz="0.000601202"/>
      </inertial>
      <visual>
        <origin xyz="-0.015 0 -0.1933" rpy="0 -1.30899700697 -3.14159265359"/>
        <geometry>
          <mesh filename="model://iCubGenova02/meshes/dae/l_upper_arm.dae" scale="0.001 0.001 0.001"/>
        </geometry>
        <material name="yellow"/>
      </visual>
      <collision>
        <origin xyz="-0.015 0 -0.1933" rpy="0 -1.30899700697 -3.14159265359"/>
        <geometry>
          <mesh filename="model://iCubGenova02/meshes/dae/l_upper_arm.dae" scale="0.001 0.001 0.001"/>
        </geometry>
      </collision>
    </link>
    <joint name="l_arm_ft_sensor" type="fixed">
      <origin xyz="0.0509301432452 0 0.0291758294659" rpy="0 -1.30899700697 3.14159265359"/>
      <parent link="l_shoulder_3"/>
      <child link="l_upper_arm"/>
      <dynamics damping="0.1"/>
    </joint>
    <link name="l_elbow_1">
      <inertial>
        <origin xyz="0.0904387263708 0.0298499 0.00921453641406" rpy="0 0 0"/>
        <mass value="1.17718"/>
        <inertia ixx="0.00107783" ixy="0.000310534" ixz="-0.00156091" iyy="0.00689571" iyz="0.000135264" izz="0.00628941"/>
      </inertial>
      <visual>
        <origin xyz="-0.259390463317 0.0339999 -0.0850325886962" rpy="0 0 0"/>
        <geometry>
          <mesh filename="model://iCubGenova02/meshes/dae/l_elbow_1.dae" scale="0.001 0.001 0.001"/>
        </geometry>
        <material name="pink"/>
      </visual>
      <collision>
        <origin xyz="-0.259390463317 0.0339999 -0.0850325886962" rpy="0 0 0"/>
        <geometry>
          <mesh filename="model://iCubGenova02/meshes/dae/l_elbow_1.dae" scale="0.001 0.001 0.001"/>
        </geometry>
      </collision>
    </link>
    <joint name="l_elbow" type="revolute">
      <origin xyz="0 0.0339999 0.07926" rpy="0 -1.30899700697 -3.14159265359"/>
      <axis xyz="2.22044604925e-16 -1.0 0.0"/>
      <parent link="l_upper_arm"/>
      <child link="l_elbow_1"/>
      <limit effort="50000" lower="0.261799387799" upper="1.85004900711" velocity="50000"/>
      <dynamics damping="0.06"/>
    </joint>
    <link name="l_forearm">
	    <inertial>
	      <origin xyz="0.0394934771963 -0.000711 0.00505345363069" rpy="0 0 0"/>
	      <mass value="0.635334"/>
	      <inertia ixx="0.000370491" ixy="4.56754e-06" ixz="-0.000105702" iyy="0.000673595" iyz="4.13735e-06" izz="0.000555689"/>
	    </inertial>
	    <visual>
	      <origin xyz="-0.297852893219 0 -0.0798094205022" rpy="0 0 0"/>
	      <geometry>
	        <mesh filename="model://iCubGenova02/meshes/dae/sim_sea_2-5_l_forearm_prt.dae" scale="0.001 0.001 0.001"/>
	      </geometry>
	      <material name="cyan"/>
	     </visual>
	     <collision>
	       <origin xyz="-0.297852893219 0 -0.0798094205022" rpy="0 0 0"/>
	       <geometry>
	         <mesh filename="model://iCubGenova02/meshes/dae/sim_sea_2-5_l_forearm_prt.dae" scale="0.001 0.001 0.001"/>
	       </geometry>
	     </collision>
    </link>
    <joint name="l_wrist_prosup" type="revolute">
      <origin xyz="0.0384624299027 0.0339999 -0.00522316819403" rpy="0 0 0"/>
      <axis xyz="0.965925843882 2.22044604925e-16 0.258818979447"/>
      <parent link="l_elbow_1"/>
      <child link="l_forearm"/>
      <limit effort="50000" lower="-1.0471975512" upper="1.0471975512" velocity="50000"/>
      <dynamics damping="0.06"/>
    </joint>
    <link name="neck_1">
      <inertial>
        <origin xyz="0.0143705608 0.006567 -0.0063841" rpy="0 0 0"/>
        <mass value="0.125793"/>
        <inertia ixx="4.0647e-05" ixy="8.09156e-08" ixz="-3.74998e-08" iyy="3.881e-05" iyz="9.39717e-06" izz="4.7535e-05"/>
      </inertial>
      <visual>
        <origin xyz="0.0142999998093 -0.079997 -0.0295007" rpy="0 0 0"/>
        <geometry>
          <mesh filename="model://iCubGenova02/meshes/dae/neck_1.dae" scale="0.001 0.001 0.001"/>
        </geometry>
        <material name="cyan"/>
      </visual>
      <collision>
        <origin xyz="0.0142999998093 -0.079997 -0.0295007" rpy="0 0 0"/>
        <geometry>
          <mesh filename="model://iCubGenova02/meshes/dae/neck_1.dae" scale="0.001 0.001 0.001"/>
        </geometry>
      </collision>
    </link>
    <joint name="neck_pitch" type="revolute">
      <origin xyz="-0.0142999998093 0.172797 0.0053118" rpy="0 0 0"/>
      <axis xyz="-1.0 0.0 0.0"/>
      <parent link="chest"/>
      <child link="neck_1"/>
      <limit effort="50000" lower="-0.698131700798" upper="0.383972435439" velocity="50000"/>
      <dynamics damping="0.06"/>
    </joint>
    <link name="neck_2">
      <inertial>
        <origin xyz="-8.8573009265e-05 0.035225 -0.01954521" rpy="0 0 0"/>
        <mass value="0.177087"/>
        <inertia ixx="0.000117943" ixy="-5.25591e-07" ixz="4.68307e-07" iyy="4.04013e-05" iyz="9.81476e-06" izz="0.000105186"/>
      </inertial>
      <visual>
        <origin xyz="0 -0.089497 -0.05030071" rpy="0 0 0"/>
        <geometry>
          <mesh filename="model://iCubGenova02/meshes/dae/neck_2.dae" scale="0.001 0.001 0.001"/>
        </geometry>
        <material name="green"/>
      </visual>
      <collision>
        <origin xyz="0 -0.089497 -0.05030071" rpy="0 0 0"/>
        <geometry>
          <mesh filename="model://iCubGenova02/meshes/dae/neck_2.dae" scale="0.001 0.001 0.001"/>
        </geometry>
      </collision>
    </link>
    <joint name="neck_roll" type="revolute">
      <origin xyz="0.0142999998093 0.0095 0.02080001" rpy="0 0 0"/>
      <axis xyz="0.0 0.0 1.0"/>
      <parent link="neck_1"/>
      <child link="neck_2"/>
      <limit effort="50000" lower="-0.349065850399" upper="0.349065850399" velocity="50000"/>
      <dynamics damping="0.06"/>
    </joint>
    <link name="head">
      <inertial>
        <origin xyz="-0.000574157809265 0.113511 -0.0075392" rpy="0 0 0"/>
        <mass value="1.50691"/>
        <inertia ixx="0.00680478" ixy="-1.60267e-05" ixz="7.28166e-05" iyy="0.00634736" iyz="0.000292091" izz="0.00478116"/>
      </inertial>
      <visual>
        <origin xyz="0 -0.067153 -0.0295007" rpy="0 0 0"/>
        <geometry>
          <mesh filename="model://iCubGenova02/meshes/dae/head.dae" scale="0.001 0.001 0.001"/>
        </geometry>
        <material name="white"/>
      </visual>
      <collision>
        <origin xyz="0 -0.067153 -0.0295007" rpy="0 0 0"/>
        <geometry>
          <mesh filename="model://iCubGenova02/meshes/dae/head.dae" scale="0.001 0.001 0.001"/>
        </geometry>
      </collision>
    </link>
    <joint name="neck_yaw" type="revolute">
      <origin xyz="0 -0.022344 -0.02080001" rpy="0 0 0"/>
      <axis xyz="0.0 1.0 0.0"/>
      <parent link="neck_2"/>
      <child link="head"/>
      <limit effort="50000" lower="-0.872664625997" upper="0.872664625997" velocity="50000"/>
      <dynamics damping="0.06"/>
    </joint>
    <link name="imu_frame"/>
    <joint name="imu_frame_fixed_joint" type="fixed">
      <origin xyz="0.00950000019074 0.133444 0.0093" rpy="-1.57079632679 1.57079632679 0"/>
      <parent link="head"/>
      <child link="imu_frame"/>
      <dynamics damping="0.1"/>
    </joint>    
    <link name="l_foot_dh_frame">
        <inertial>
            <mass value="0" />
            <origin xyz="0 0 0" rpy="0 -0 0" />
            <inertia ixx="0" ixy="0" ixz="0" iyy="0" iyz="0" izz="0" />
        </inertial>
    </link>
    <joint name="l_foot_dh_frame_fixed_joint" type="fixed">
        <origin xyz="-0.0263 0 -0.0143" rpy="0 1.5708 0" />
        <axis xyz="0 0 0" />
        <parent link="l_foot" />
        <child link="l_foot_dh_frame" />
    </joint>
    <link name="r_foot_dh_frame">
        <inertial>
            <mass value="0" />
            <origin xyz="0 0 0" rpy="0 -0 0" />
            <inertia ixx="0" ixy="0" ixz="0" iyy="0" iyz="0" izz="0" />
        </inertial>
    </link>
    <joint name="r_foot_dh_frame_fixed_joint" type="fixed">
        <origin xyz="-0.0263 0 -0.0143" rpy="0 1.5708 0" />
        <axis xyz="0 0 0" />
        <parent link="r_foot" />
        <child link="r_foot_dh_frame" />
    </joint>
    <gazebo reference="l_arm_ft_sensor">
        <sensor name="left_arm_ft" type="force_torque">
            <force_torque>
                <frame>child</frame>
                <measure_direction>child_to_parent</measure_direction>
            </force_torque>
            <update_rate>100</update_rate>
            <always_on>1</always_on>
        </sensor>
    </gazebo>
    <gazebo reference="r_arm_ft_sensor">
        <sensor name="right_arm_ft" type="force_torque">
            <force_torque>
                <frame>child</frame>
                <measure_direction>child_to_parent</measure_direction>
            </force_torque>
            <update_rate>100</update_rate>
            <always_on>1</always_on>
        </sensor>
    </gazebo>
    <gazebo reference="l_leg_ft_sensor">
        <sensor name="left_leg_ft" type="force_torque">
            <force_torque>
                <frame>child</frame>
                <measure_direction>child_to_parent</measure_direction>
            </force_torque>
            <update_rate>100</update_rate>
            <always_on>1</always_on>
        </sensor>
    </gazebo>
    <gazebo reference="r_leg_ft_sensor">
        <sensor name="right_leg_ft" type="force_torque">
            <force_torque>
                <frame>child</frame>
                <measure_direction>child_to_parent</measure_direction>
            </force_torque>
            <update_rate>100</update_rate>
            <always_on>1</always_on>
        </sensor>
    </gazebo>
    <gazebo reference="l_foot_ft_sensor">
        <sensor name="left_foot_ft" type="force_torque">
            <force_torque>
                <frame>child</frame>
                <measure_direction>child_to_parent</measure_direction>
            </force_torque>
            <update_rate>100</update_rate>
            <always_on>1</always_on>
        </sensor>
    </gazebo>
    <gazebo reference="r_foot_ft_sensor">
        <sensor name="right_foot_ft" type="force_torque">
            <force_torque>
                <frame>child</frame>
                <measure_direction>child_to_parent</measure_direction>
            </force_torque>
            <update_rate>100</update_rate>
            <always_on>1</always_on>
        </sensor>
    </gazebo>


    <!-- <link name="chest_skin_frame">
        <inertial>
            <mass value="0" />
            <origin xyz="0 0 0" rpy="0 -0 0" />
            <inertia ixx="0" ixy="0" ixz="0" iyy="0" iyz="0" izz="0" />
        </inertial>
    </link> -->
    <!-- <link name="codyco_balancing_world">
        <inertial>
            <mass value="0" />
            <origin xyz="0 0 0" rpy="0 -0 0" />
            <inertia ixx="0" ixy="0" ixz="0" iyy="0" iyz="0" izz="0" />
        </inertial>
    </link> -->
    <!-- This together with r_forearm have been divided into pronosup links/koints -->
    <!-- <link name="l_forearm">
        <inertial>
            <mass value="0.525" />
            <origin xyz="0.000347 0.066 0.00476" rpy="0 -0 0" />
            <inertia ixx="0.000765393" ixy="4.337e-06" ixz="2.39e-07" iyy="0.000164578" iyz="1.9381e-05" izz="0.00069806" />
        </inertial>
        <visual>
            <origin xyz="-0.000143922 -1.25974e-12 0.0204334" rpy="0.477647 1.5708 2.04844" />
            <geometry>
                <mesh filename="meshes/visual/icub_l_forearm.dae" scale="1 1 1" />
            </geometry>
            <material name="material.metal">
                <texture />
                <color rgba="0 0 0 1" />
            </material>
        </visual>
        <collision>
            <origin xyz="-0.000143922 -1.25974e-12 0.0204334" rpy="0.477647 1.5708 2.04844" />
            <geometry>
                <mesh filename="meshes/collision/icub_simple_collision_l_forearm.dae" scale="1 1 1" />
            </geometry>
        </collision>
    </link> -->
    <!-- <link name="l_forearm_dh_frame">
        <inertial>
            <mass value="0" />
            <origin xyz="0 0 0" rpy="0 -0 0" />
            <inertia ixx="0" ixy="0" ixz="0" iyy="0" iyz="0" izz="0" />
        </inertial>
    </link> -->
    <!-- <link name="l_gripper">
        <inertial>
            <mass value="0" />
            <origin xyz="0 0 0" rpy="0 -0 0" />
            <inertia ixx="0" ixy="0" ixz="0" iyy="0" iyz="0" izz="0" />
        </inertial>
    </link> -->
    <!-- <link name="l_hand">
        <inertial>
            <mass value="0.213" />
            <origin xyz="0.07023 -0.00805 -0.007" rpy="0 -0 0" />
            <inertia ixx="0.000157143" ixy="1.278e-05" ixz="4.823e-06" iyy="0.000247995" iyz="-1.8188e-05" izz="0.000380535" />
        </inertial>
        <visual>
            <origin xyz="-1.25973e-12 0.0204334 -0.000143922" rpy="5.10271e-12 -2.64186e-12 1.49622e-11" />
            <geometry>
                <mesh filename="meshes/visual/icub_l_hand.dae" scale="1 1 1" />
            </geometry>
            <material name="material.metal">
                <texture />
                <color rgba="0 0 0 1" />
            </material>
        </visual>
        <collision>
            <origin xyz="-1.25973e-12 0.0204334 -0.000143922" rpy="5.10271e-12 -2.64186e-12 1.49622e-11" />
            <geometry>
                <mesh filename="meshes/collision/icub_simple_collision_l_hand.dae" scale="1 1 1" />
            </geometry>
        </collision>
    </link> -->
    <!-- <link name="l_hand_dh_frame">
        <inertial>
            <mass value="0" />
            <origin xyz="0 0 0" rpy="0 -0 0" />
            <inertia ixx="0" ixy="0" ixz="0" iyy="0" iyz="0" izz="0" />
        </inertial>
    </link> -->
    <!-- <link name="l_upper_arm_dh_frame">
        <inertial>
            <mass value="0" />
            <origin xyz="0 0 0" rpy="0 -0 0" />
            <inertia ixx="0" ixy="0" ixz="0" iyy="0" iyz="0" izz="0" />
        </inertial>
    </link> -->
    <!-- <link name="l_wrist_1">
        <inertial>
            <mass value="0" />
            <origin xyz="0 0 0" rpy="0 -0 0" />
            <inertia ixx="0" ixy="0" ixz="0" iyy="0" iyz="0" izz="0" />
        </inertial>
    </link> -->
    <!-- This together with r_forearm have been divided into pronosup links/koints -->
    <!-- <link name="r_forearm">
        <inertial>
            <mass value="0.525" />
            <origin xyz="-0.000347 -0.066 -0.00476" rpy="0 -0 0" />
            <inertia ixx="0.000766" ixy="5.66e-06" ixz="1.4e-06" iyy="0.000164" iyz="1.82e-05" izz="0.000699" />
        </inertial>
        <visual>
            <origin xyz="0.000143922 -1.07214e-12 -0.0204334" rpy="1.39994 1.5708 2.97073" />
            <geometry>
                <mesh filename="meshes/visual/icub_r_forearm.dae" scale="1 1 1" />
            </geometry>
            <material name="material.metal">
                <texture />
                <color rgba="0 0 0 1" />
            </material>
        </visual>
        <collision>
            <origin xyz="0.000143922 -1.07214e-12 -0.0204334" rpy="1.39994 1.5708 2.97073" />
            <geometry>
                <mesh filename="meshes/collision/icub_simple_collision_r_forearm.dae" scale="1 1 1" />
            </geometry>
        </collision>
    </link> -->
    <!-- <link name="r_forearm_dh_frame">
        <inertial>
            <mass value="0" />
            <origin xyz="0 0 0" rpy="0 -0 0" />
            <inertia ixx="0" ixy="0" ixz="0" iyy="0" iyz="0" izz="0" />
        </inertial>
    </link> -->
    <!-- <link name="r_gripper">
        <inertial>
            <mass value="0" />
            <origin xyz="0 0 0" rpy="0 -0 0" />
            <inertia ixx="0" ixy="0" ixz="0" iyy="0" iyz="0" izz="0" />
        </inertial>
    </link> -->
    <!-- <link name="r_hand">
        <inertial>
            <mass value="0.213" />
            <origin xyz="0.07023 -0.00805 0.007" rpy="0 -0 0" />
            <inertia ixx="0.000154" ixy="1.26e-05" ixz="-6.08e-06" iyy="0.00025" iyz="1.76e-05" izz="0.000378" />
        </inertial>
        <visual>
            <origin xyz="1.0721e-12 0.0204334 0.000143922" rpy="1.53098e-11 2.00656e-11 -3.14159" />
            <geometry>
                <mesh filename="meshes/visual/icub_r_hand.dae" scale="1 1 1" />
            </geometry>
            <material name="material.metal">
                <texture />
                <color rgba="0 0 0 1" />
            </material>
        </visual>
        <collision>
            <origin xyz="1.0721e-12 0.0204334 0.000143922" rpy="1.53098e-11 2.00656e-11 -3.14159" />
            <geometry>
                <mesh filename="meshes/collision/icub_simple_collision_r_hand.dae" scale="1 1 1" />
            </geometry>
        </collision>
    </link> -->
    <!-- <link name="r_hand_dh_frame">
        <inertial>
            <mass value="0" />
            <origin xyz="0 0 0" rpy="0 -0 0" />
            <inertia ixx="0" ixy="0" ixz="0" iyy="0" iyz="0" izz="0" />
        </inertial>
    </link> -->
    <!-- <link name="r_upper_arm_dh_frame">
        <inertial>
            <mass value="0" />
            <origin xyz="0 0 0" rpy="0 -0 0" />
            <inertia ixx="0" ixy="0" ixz="0" iyy="0" iyz="0" izz="0" />
        </inertial>
    </link> -->
    <!-- <link name="r_wrist_1">
        <inertial>
            <mass value="0" />
            <origin xyz="0 0 0" rpy="0 -0 0" />
            <inertia ixx="0" ixy="0" ixz="0" iyy="0" iyz="0" izz="0" />
        </inertial>
    </link> -->
    <!-- <link name="torso">
        <inertial>
            <mass value="0" />
            <origin xyz="0 0 0" rpy="0 -0 0" />
            <inertia ixx="0" ixy="0" ixz="0" iyy="0" iyz="0" izz="0" />
        </inertial>
    </link> -->
    <!-- <joint name="chest_skin_frame_fixed_joint" type="fixed">
        <origin xyz="0.00231 0.1933 -1.18362e-17" rpy="-1.8747e-33 5.77686e-66 6.16298e-33" />
        <axis xyz="0 0 0" />
        <parent link="chest" />
        <child link="chest_skin_frame" />
    </joint> -->
    <!-- <joint name="codyco_balancing_world_fixed_joint" type="fixed">
        <origin xyz="-0.0263 -5.66898e-35 -0.0143" rpy="3.14159 -0 0" />
        <axis xyz="0 0 0" />
        <parent link="l_foot" />
        <child link="codyco_balancing_world" />
    </joint> -->
    <!-- <joint name="l_wrist_prosup" type="revolute">
        <origin xyz="-0.015 0 0" rpy="1.5708 -0 -1.5708" />
        <axis xyz="0 1 6.12323e-17" />
        <parent link="l_elbow_1" />
        <child link="l_forearm" />
        <dynamics damping="1" friction="0" />
        <limit effort="0.45" velocity="100" lower="-0.872665" upper="0.872665" />
    </joint> -->
    <!-- <joint name="l_forearm_dh_frame_fixed_joint" type="fixed">
        <origin xyz="0 0.1373 8.4072e-18" rpy="0 -0 0" />
        <axis xyz="0 0 0" />
        <parent link="l_forearm" />
        <child link="l_forearm_dh_frame" />
    </joint> -->
    <!-- <joint name="l_gripper_joint" type="fixed">
        <origin xyz="0.0625 0 -0.016" rpy="0 -0 0" />
        <axis xyz="0 0 0" />
        <parent link="l_hand" />
        <child link="l_gripper" />
    </joint> -->
    <!-- <joint name="l_wrist_yaw" type="revolute">
        <origin xyz="0 0 0" rpy="0 -0 0" />
        <axis xyz="0 0 1" />
        <parent link="l_wrist_1" />
        <child link="l_hand" />
        <dynamics damping="1" friction="0" />
        <limit effort="0.65" velocity="100" lower="-0.436332" upper="0.436332" />
    </joint> -->
    <!-- <joint name="l_hand_dh_frame_fixed_joint" type="fixed">
        <origin xyz="0.0625 0 -0.016" rpy="0 -0 0" />
        <axis xyz="0 0 0" />
        <parent link="l_hand" />
        <child link="l_hand_dh_frame" />
    </joint> -->
    <!-- <joint name="l_upper_arm_dh_frame_fixed_joint" type="fixed">
        <origin xyz="0 0 0.08428" rpy="-1.5708 0 0" />
        <axis xyz="0 0 0" />
        <parent link="l_upper_arm" />
        <child link="l_upper_arm_dh_frame" />
    </joint> -->
    <!-- <joint name="l_wrist_pitch" type="revolute">
        <origin xyz="0 0.1373 8.4072e-18" rpy="1.5708 -0 1.5708" />
        <axis xyz="0 1 6.12323e-17" />
        <parent link="l_forearm" />
        <child link="l_wrist_1" />
        <dynamics damping="1" friction="0" />
        <limit effort="0.65" velocity="100" lower="-1.13446" upper="0.174533" />
    </joint> -->
    <!-- <joint name="r_wrist_prosup" type="revolute">
        <origin xyz="0.015 0 0" rpy="1.5708 -0 -1.5708" />
        <axis xyz="0 1 6.12323e-17" />
        <parent link="r_elbow_1" />
        <child link="r_forearm" />
        <dynamics damping="1" friction="0" />
        <limit effort="0.45" velocity="100" lower="-0.872665" upper="0.872665" />
    </joint> -->
    <!-- <joint name="r_forearm_dh_frame_fixed_joint" type="fixed">
        <origin xyz="0 -0.1373 -8.4072e-18" rpy="0 -0 0" />
        <axis xyz="0 0 0" />
        <parent link="r_forearm" />
        <child link="r_forearm_dh_frame" />
    </joint> -->
    <!-- <joint name="r_gripper_joint" type="fixed">
        <origin xyz="0.0625 0 0.016" rpy="0 -0 0" />
        <axis xyz="0 0 0" />
        <parent link="r_hand" />
        <child link="r_gripper" />
    </joint> -->
    <!-- <joint name="r_wrist_yaw" type="revolute">
        <origin xyz="0 0 0" rpy="0 -0 3.14159" />
        <axis xyz="0 0 1" />
        <parent link="r_wrist_1" />
        <child link="r_hand" />
        <dynamics damping="1" friction="0" />
        <limit effort="0.65" velocity="100" lower="-0.436332" upper="0.436332" />
    </joint> -->
    <!-- <joint name="r_hand_dh_frame_fixed_joint" type="fixed">
        <origin xyz="0.0625 0 0.016" rpy="0 -0 0" />
        <axis xyz="0 0 0" />
        <parent link="r_hand" />
        <child link="r_hand_dh_frame" />
    </joint> -->
    <!-- <joint name="r_upper_arm_dh_frame_fixed_joint" type="fixed">
        <origin xyz="0 0 0.08428" rpy="1.5708 -0 3.14159" />
        <axis xyz="0 0 0" />
        <parent link="r_upper_arm" />
        <child link="r_upper_arm_dh_frame" />
    </joint> -->
    <!-- <joint name="r_wrist_pitch" type="revolute">
        <origin xyz="0 -0.1373 -8.4072e-18" rpy="1.5708 -0 1.5708" />
        <axis xyz="0 1 6.12323e-17" />
        <parent link="r_forearm" />
        <child link="r_wrist_1" />
        <dynamics damping="1" friction="0" />
        <limit effort="0.65" velocity="100" lower="-1.13446" upper="0.174533" />
    </joint> -->
    <!-- <joint name="torso_joint" type="fixed">
        <origin xyz="0.00231 0.1933 -1.18362e-17" rpy="0 -0 0" />
        <axis xyz="0 0 0" />
        <parent link="chest" />
        <child link="torso" />
    </joint> -->
</robot>
