<robot name="test_icub">
    <link name="base_link" />
    <link name="chest">
        <inertial>
            <mass value="4.81" />
            <origin xyz="0.00222898 0.075 -1.18362e-17" rpy="0 -0 0" />
            <inertia ixx="0.07472" ixy="-3.6e-06" ixz="-4.705e-05" iyy="0.08145" iyz="0.004567" izz="0.01306" />
        </inertial>
        <visual>
            <origin xyz="-0.0055 -6.93889e-18 -3.55271e-18" rpy="2.03442 -1.5708 -0.463617" />
            <geometry>
                <mesh filename="meshes/visual/icub_chest.dae" scale="1 1 1" />
            </geometry>
            <material name="material.metal">
                <texture />
                <color rgba="0 0 0 1" />
            </material>
        </visual>
        <collision>
            <origin xyz="-0.0055 -6.93889e-18 -3.55271e-18" rpy="2.03442 -1.5708 -0.463617" />
            <geometry>
                <mesh filename="meshes/collision/icub_simple_collision_chest.dae" scale="1 1 1" />
            </geometry>
        </collision>
    </link>
    <link name="head">
        <inertial>
            <mass value="3" />
            <origin xyz="0.0185 -0.1108 6.78454e-18" rpy="0 -0 0" />
            <inertia ixx="0" ixy="0" ixz="0" iyy="0" iyz="0" izz="0" />
        </inertial>
        <visual>
            <origin xyz="0.0045 -0.0235 9.42472e-13" rpy="1.81577 1.5708 0.244969" />
            <geometry>
                <mesh filename="meshes/visual/icub_head.dae" scale="1 1 1" />
            </geometry>
            <material name="material.metal">
                <texture />
                <color rgba="0 0 0 1" />
            </material>
        </visual>
        <collision>
            <origin xyz="0.0045 -0.0235 9.42472e-13" rpy="1.81577 1.5708 0.244969" />
            <geometry>
                <mesh filename="meshes/collision/icub_simple_collision_head.dae" scale="1 1 1" />
            </geometry>
        </collision>
    </link>
    <link name="imu_frame">
        <inertial>
            <mass value="0" />
            <origin xyz="0 0 0" rpy="0 -0 0" />
            <inertia ixx="0" ixy="0" ixz="0" iyy="0" iyz="0" izz="0" />
        </inertial>
    </link>
    <link name="neck_1">
        <inertial>
            <mass value="0" />
            <origin xyz="0 0 0" rpy="0 -0 0" />
            <inertia ixx="0" ixy="0" ixz="0" iyy="0" iyz="0" izz="0" />
        </inertial>
        <visual>
            <origin xyz="-5.55112e-17 9.62889e-13 -0.0055" rpy="-7.25153e-06 -1.5708 -1.57079" />
            <geometry>
                <mesh filename="meshes/visual/icub_neck_1.dae" scale="1 1 1" />
            </geometry>
            <material name="material.metal">
                <texture />
                <color rgba="0 0 0 1" />
            </material>
        </visual>
        <collision>
            <origin xyz="-5.55112e-17 9.62889e-13 -0.0055" rpy="-7.25153e-06 -1.5708 -1.57079" />
            <geometry>
                <mesh filename="meshes/collision/icub_simple_collision_neck_1.dae" scale="1 1 1" />
            </geometry>
        </collision>
    </link>
    <link name="neck_2">
        <inertial>
            <mass value="0" />
            <origin xyz="0 0 0" rpy="0 -0 0" />
            <inertia ixx="0" ixy="0" ixz="0" iyy="0" iyz="0" izz="0" />
        </inertial>
        <visual>
            <origin xyz="-9.62885e-13 0.0055 0.0235" rpy="2.17538e-05 -1.5708 1.57077" />
            <geometry>
                <mesh filename="meshes/visual/icub_neck_2.dae" scale="1 1 1" />
            </geometry>
            <material name="material.metal">
                <texture />
                <color rgba="0 0 0 1" />
            </material>
        </visual>
        <collision>
            <origin xyz="-9.62885e-13 0.0055 0.0235" rpy="2.17538e-05 -1.5708 1.57077" />
            <geometry>
                <mesh filename="meshes/collision/icub_simple_collision_neck_2.dae" scale="1 1 1" />
            </geometry>
        </collision>
    </link>
    <link name="r_arm">
        <inertial>
            <mass value="0.729" />
            <origin xyz="0.00015906 -0.0543972 8.28733e-05" rpy="0 -0 0" />
            <inertia ixx="0.000408" ixy="2.29e-06" ixz="1.08e-06" iyy="0.00026" iyz="3.57e-06" izz="0.00038" />
        </inertial>
        <visual>
            <origin xyz="0.0204334 -0.15228 -0.000143922" rpy="-1.5708 -1.309 3.14159" />
            <geometry>
                <mesh filename="meshes/visual/icub_r_arm.dae" scale="1 1 1" />
            </geometry>
            <material name="material.metal">
                <texture />
                <color rgba="0 0 0 1" />
            </material>
        </visual>
        <collision>
            <origin xyz="0.0204334 -0.15228 -0.000143922" rpy="-1.5708 -1.309 3.14159" />
            <geometry>
                <mesh filename="meshes/collision/icub_simple_collision_r_arm.dae" scale="1 1 1" />
            </geometry>
        </collision>
    </link>
    <link name="r_elbow_1">
        <inertial>
            <mass value="0.074" />
            <origin xyz="0.0013 -0.00371 0.00105" rpy="0 -0 0" />
            <inertia ixx="2.84e-05" ixy="-5.02e-07" ixz="-3.99e-07" iyy="9.24e-06" iyz="-3.71e-07" izz="2.99e-05" />
        </inertial>
    </link>
    <link name="r_forearm">
        <inertial>
            <mass value="0.525" />
            <origin xyz="-0.000347 -0.066 -0.00476" rpy="0 -0 0" />
            <inertia ixx="0.000766" ixy="5.66e-06" ixz="1.4e-06" iyy="0.000164" iyz="1.82e-05" izz="0.000699" />
        </inertial>
        <visual>
            <origin xyz="0.000143922 -1.07213e-12 -0.0204334" rpy="1.39993 1.5708 2.97073" />
            <geometry>
                <mesh filename="meshes/visual/icub_r_forearm.dae" scale="1 1 1" />
            </geometry>
            <material name="material.metal">
                <texture />
                <color rgba="0 0 0 1" />
            </material>
        </visual>
        <collision>
            <origin xyz="0.000143922 -1.07213e-12 -0.0204334" rpy="1.39993 1.5708 2.97073" />
            <geometry>
                <mesh filename="meshes/collision/icub_simple_collision_r_forearm.dae" scale="1 1 1" />
            </geometry>
        </collision>
    </link>
    <link name="r_gripper">
        <inertial>
            <mass value="0" />
            <origin xyz="0 0 0" rpy="0 -0 0" />
            <inertia ixx="0" ixy="0" ixz="0" iyy="0" iyz="0" izz="0" />
        </inertial>
    </link>
    <link name="r_hand">
        <inertial>
            <mass value="0.213" />
            <origin xyz="0.07023 -0.00805 0.007" rpy="0 -0 0" />
            <inertia ixx="0.000154" ixy="1.26e-05" ixz="-6.08e-06" iyy="0.00025" iyz="1.76e-05" izz="0.000378" />
        </inertial>
        <visual>
            <origin xyz="1.0721e-12 0.0204334 0.000143922" rpy="1.53098e-11 2.00653e-11 -3.14159" />
            <geometry>
                <mesh filename="meshes/visual/icub_r_hand.dae" scale="1 1 1" />
            </geometry>
            <material name="material.metal">
                <texture />
                <color rgba="0 0 0 1" />
            </material>
        </visual>
        <collision>
            <origin xyz="1.0721e-12 0.0204334 0.000143922" rpy="1.53098e-11 2.00653e-11 -3.14159" />
            <geometry>
                <mesh filename="meshes/collision/icub_simple_collision_r_hand.dae" scale="1 1 1" />
            </geometry>
        </collision>
    </link>
    <link name="r_shoulder_1">
        <inertial>
            <mass value="0.189" />
            <origin xyz="5e-06 0.0187 0.00119" rpy="0 -0 0" />
            <inertia ixx="0.000123" ixy="2.1e-08" ixz="-1e-09" iyy="2.44e-05" iyz="4.22e-06" izz="0.000113" />
        </inertial>
        <visual>
            <origin xyz="-3.08642e-14 0.109285 0.00521101" rpy="-0.0815582 1.5708 1.48924" />
            <geometry>
                <mesh filename="meshes/visual/icub_r_shoulder_1.dae" scale="1 1 1" />
            </geometry>
            <material name="material.metal">
                <texture />
                <color rgba="0 0 0 1" />
            </material>
        </visual>
        <collision>
            <origin xyz="-3.08642e-14 0.109285 0.00521101" rpy="-0.0815582 1.5708 1.48924" />
            <geometry>
                <mesh filename="meshes/collision/icub_simple_collision_r_shoulder_1.dae" scale="1 1 1" />
            </geometry>
        </collision>
    </link>
    <link name="r_shoulder_2">
        <inertial>
            <mass value="0.179" />
            <origin xyz="-9.4e-05 -0.00627 -0.0166" rpy="0 -0 0" />
            <inertia ixx="0.000137" ixy="-4.53e-07" ixz="2.03e-07" iyy="8.3e-05" iyz="2.07e-05" izz="9.93e-05" />
        </inertial>
        <visual>
            <origin xyz="-0.00154529 -0.00521101 -1.11181e-12" rpy="2.14034 -1.5708 -0.56954" />
            <geometry>
                <mesh filename="meshes/visual/icub_r_shoulder_2.dae" scale="1 1 1" />
            </geometry>
            <material name="material.metal">
                <texture />
                <color rgba="0 0 0 1" />
            </material>
        </visual>
        <collision>
            <origin xyz="-0.00154529 -0.00521101 -1.11181e-12" rpy="2.14034 -1.5708 -0.56954" />
            <geometry>
                <mesh filename="meshes/collision/icub_simple_collision_r_shoulder_2.dae" scale="1 1 1" />
            </geometry>
        </collision>
    </link>
    <link name="r_upper_arm">
        <inertial>
            <mass value="0.155" />
            <origin xyz="0.00553932 -2.47652e-05 0.0493895" rpy="0 -0 0" />
            <inertia ixx="3.44122e-05" ixy="3.56977e-07" ixz="-3.95372e-06" iyy="4.33544e-05" iyz="-6.5128e-06" izz="6.49393e-05" />
        </inertial>
    </link>
    <link name="r_wrist_1">
        <inertial>
            <mass value="0" />
            <origin xyz="0 0 0" rpy="0 -0 0" />
            <inertia ixx="0" ixy="0" ixz="0" iyy="0" iyz="0" izz="0" />
        </inertial>
    </link>
    <joint name="neck_yaw" type="revolute">
        <origin xyz="-5.77779e-34 0 0" rpy="-1.5708 -0 1.5708" />
        <axis xyz="0 -1 6.12323e-17" />
        <parent link="neck_2" />
        <child link="head" />
        <dynamics damping="0.1" friction="0" />
        <limit effort="20" velocity="100" lower="-0.959931" upper="0.959931" />
    </joint>
    <joint name="imu_frame_fixed_joint" type="fixed">
        <origin xyz="0.0185 -0.1108 0.0066" rpy="1.5708 -0 0" />
        <axis xyz="0 0 0" />
        <parent link="head" />
        <child link="imu_frame" />
    </joint>
    <joint name="neck_pitch" type="revolute">
        <origin xyz="0.00231 0.1933 -1.18362e-17" rpy="1.5708 -0 1.5708" />
        <axis xyz="0 1 6.12323e-17" />
        <parent link="chest" />
        <child link="neck_1" />
        <dynamics damping="0.1" friction="0" />
        <limit effort="20" velocity="100" lower="-0.698132" upper="0.523599" />
    </joint>
    <joint name="neck_roll" type="revolute">
        <origin xyz="0.0095 0 0" rpy="-1.5708 -0 -1.5708" />
        <axis xyz="0 -1 6.12323e-17" />
        <parent link="neck_1" />
        <child link="neck_2" />
        <dynamics damping="0.1" friction="0" />
        <limit effort="20" velocity="100" lower="-1.22173" upper="1.0472" />
    </joint>
    <joint name="r_arm_ft_sensor" type="fixed">
        <origin xyz="0.015 -8.93429e-18 0.15228" rpy="1.5708 -0 3.14159" />
        <axis xyz="0 0 0" />
        <parent link="r_upper_arm" />
        <child link="r_arm" />
    </joint>
    <joint name="r_elbow" type="revolute">
        <origin xyz="0 0 0" rpy="1.5708 -0 0" />
        <axis xyz="0 1 6.12323e-17" />
        <parent link="r_arm" />
        <child link="r_elbow_1" />
        <dynamics damping="0.1" friction="0" />
        <limit effort="20" velocity="100" lower="0.0959931" upper="1.85005" />
    </joint>
    <joint name="r_wrist_prosup" type="revolute">
        <origin xyz="0.015 0 0" rpy="1.5708 -0 -1.5708" />
        <axis xyz="0 1 6.12323e-17" />
        <parent link="r_elbow_1" />
        <child link="r_forearm" />
        <dynamics damping="0.1" friction="0" />
        <limit effort="0.45" velocity="100" lower="-0.872665" upper="0.872665" />
    </joint>
    <joint name="r_gripper_joint" type="fixed">
        <origin xyz="0.0625 0 0.016" rpy="0 -0 0" />
        <axis xyz="0 0 0" />
        <parent link="r_hand" />
        <child link="r_gripper" />
    </joint>
    <joint name="r_wrist_yaw" type="revolute">
        <origin xyz="0 0 0" rpy="0 -0 3.14159" />
        <axis xyz="0 0 1" />
        <parent link="r_wrist_1" />
        <child link="r_hand" />
        <dynamics damping="0.1" friction="0" />
        <limit effort="0.65" velocity="100" lower="-0.436332" upper="0.436332" />
    </joint>
    <joint name="r_shoulder_pitch" type="revolute">
        <origin xyz="0.00525 0.1433 0.11026" rpy="-1.309 -0 1.5708" />
        <axis xyz="0 1 5.55112e-17" />
        <parent link="chest" />
        <child link="r_shoulder_1" />
        <dynamics damping="0.1" friction="0" />
        <limit effort="84" velocity="100" lower="-1.65806" upper="0.0872665" />
    </joint>
    <joint name="r_shoulder_roll" type="revolute">
        <origin xyz="0 0 0" rpy="-1.5708 -0 -1.5708" />
        <axis xyz="0 -1 6.12323e-17" />
        <parent link="r_shoulder_1" />
        <child link="r_shoulder_2" />
        <dynamics damping="0.1" friction="0" />
        <limit effort="84" velocity="100" lower="0" upper="2.80649" />
    </joint>
    <joint name="r_shoulder_yaw" type="revolute">
        <origin xyz="-4.33681e-19 0 0" rpy="3.14159 -0 1.309" />
        <axis xyz="0 6.12323e-17 -1" />
        <parent link="r_shoulder_2" />
        <child link="r_upper_arm" />
        <dynamics damping="0.1" friction="0" />
        <limit effort="34" velocity="100" lower="-0.645772" upper="1.74533" />
    </joint>
    <joint name="r_wrist_pitch" type="revolute">
        <origin xyz="0 -0.1373 -8.4072e-18" rpy="1.5708 -0 1.5708" />
        <axis xyz="0 1 6.12323e-17" />
        <parent link="r_forearm" />
        <child link="r_wrist_1" />
        <dynamics damping="0.1" friction="0" />
        <limit effort="0.65" velocity="100" lower="-1.13446" upper="0.174533" />
    </joint>
    <joint name="base_fixed_joint" type="fixed">
        <origin xyz="0 0 0" rpy="0 -0 0" />
        <axis xyz="0 0 0" />
        <parent link="base_link" />
        <child link="chest" />
    </joint>
    <gazebo reference="r_arm_ft_sensor">
        <sensor name="right_arm_ft" type="force_torque">
            <force_torque>
                <frame>child</frame>
                <measure_direction>child_to_parent</measure_direction>
            </force_torque>
            <update_rate>100</update_rate>
            <always_on>1</always_on>
        </sensor>
    </gazebo>
</robot>
